Workbook

Sheet SETUP
A1: RENEWAL MANAGEMENT TOOL — PROPERTY SETUP
A2: PROPERTY CONFIGURATION
A3: Property Name: | B3: RISE Bartram Park | C3: ← Enter your property name here (blue = input cell)
A4: Month / Year: | B4: April 2026 | C4: ← Enter month and year (e.g., 'April 2026')
A6: FLOOR PLAN CONFIGURATION — Rates & Occupancy by Unit Type
A7: Enter each floor plan type, its current market rate, budget rate, and occupancy status. The renewal tracker sheet uses these values to auto-populate offers — just enter the Unit Type and everything calculates.
A8: Floor Plan Type | B8: Market Rate ($) | C8: Budget Rate ($) | D8: Occupancy Status (Under / Over) | E8: Unit Description / Notes
A9: A1 | B9: 1595 | C9: 1504 | D9: Under | E9: 1 Bed / 1 Bath
A10: A2 | B10: 1795 | C10: 1476 | D10: Over | E10: 1 Bed / 1 Bath
A11: A3 | B11: 1878 | C11: 1727 | D11: Under | E11: 1 Bed / 1 Bath
A12: A4 | B12: 1421 | C12: 1424 | D12: Over | E12: 1 Bed / 1 Bath
A13: A5 | B13: 1719 | C13: 1561 | D13: Under | E13: 1 Bed / 1 Bath
A14: B1 | B14: 1809 | C14: 1764 | D14: Under | E14: 2 Bed / 2 Bath
A15: B2 | B15: 1595 | C15: 1806 | D15: Under | E15: 2 Bed / 2 Bath
A16: B3 | B16: 1880 | C16: 1976 | D16: Under | E16: 2 Bed / 2 Bath
A17: B4 | B17: 1942 | C17: 1845 | D17: Over | E17: 2 Bed / 2 Bath
A18: B5 | B18: 1860 | C18: 1776 | D18: Over | E18: 2 Bed / 2 Bath
A19: B6 | B19: 1880 | C19: 1789 | D19: Under | E19: 2 Bed / 2 Bath
A20: B7 | B20: 2047 | C20: 1821 | D20: Over | E20: 2 Bed / 2 Bath
... A24: S2 | B24: 1301 | C24: 1298 | D24: Over | E24: 0 Bed / 1 Bath
A25: ⚠ Occupancy Status: Type "Under" when floor plan is below occupancy budget target, "Over" when above it. This controls which offer formula tier is applied.
A27: HOW TO USE THIS TOOL
A28: Step 1 — Configure: | B28: Update Property Name and Month/Year above. Enter all floor plan types with market rates, budget rates, and occupancy status (Under/Over). These feed every renewal sheet automatically.
A29: Step 2 — Enter Residents: | B29: Go to the monthly renewal sheet (e.g., 'Mar 2026'). Type resident data in the orange columns: Name, Unit, Unit Type, Expiration Date, Deposit Held, and Current Rate. All other columns calculate automatically.
A30: Step 3 — Track Decisions: | B30: As decisions come in, enter dates or notes in the Renewal Signed, Transfer, or NTV Rcv'd columns. Rows auto-color: Green = Renewed, Red = NTV, Blue = Transfer, Yellow = Pending.
A31: Step 4 — New Month: | B31: Right-click the TEMPLATE tab → 'Move or Copy' → check 'Create a copy' → rename to new month (e.g., 'Apr 2026'). Update Month/Year in this SETUP sheet.
A32: Step 5 — New Property: | B32: Save a copy of this entire workbook with the new property name. Then update SETUP with the new property name and its floor plan configuration. All sheets reference SETUP automatically.
A34: ROW COLOR CODING (auto-applied based on status entries)
A35: Renewed | B35: A date/value entered in 'Renewal Signed' column (N) turns the row green
A36: NTV (Notice to Vacate) | B36: A date/value entered in 'NTV Rcv'd' column (P) turns the row red
A37: Transfer | B37: A date/value entered in 'Transfer' column (O) turns the row blue
A38: Pending Signature | B38: Color manually with yellow fill using Excel's fill tool
A39: MTM (Month-to-Month) | B39: Color manually with gray fill using Excel's fill tool

Sheet March 2026
A1: =SETUP!B3&" - "&SETUP!B4&" Renewals" -> RISE Bartram Park - April 2026 Renewals
A2: Name | B2: Unit | C2: Unit Type | D2: Expiration Date | E2: 90-Day Notice | F2: 60-Day Notice | G2: 30-Day Notice | H2: Deposit Held | I2: Current Rate | J2: Recommended Offer | K2: Investor Override % Increase | L2: Investor Override Offer | M2: Offer 1 Conservative | N2: Offer 2 Balanced | O2: Offer 3 Aggressive | P2: Signed Offer | Q2: Renewal Signed | R2: Transfer | S2: NTV Rcv'd | T2: Phone | U2: Notes | V2: Market Rate | W2: Budget | X2: Occupancy (Under/Over) | Y2: Rent Growth Offer 1 | Z2: Rent Growth Offer 2 | AA2: Rent Growth Offer 3 | AB2: Signed Rent Growth
A3: ▼ Enter | B3: ▼ Enter | C3: ▼ Enter | D3: ▼ Enter | E3: ◀ Auto | F3: ◀ Auto | G3: ◀ Auto | H3: ▼ Enter | I3: ▼ Enter | J3: ◀ Auto | K3: ▼ Enter | L3: ◀ Auto | M3: ◀ Auto | N3: ◀ Auto | O3: ◀ Auto | P3: ▼ Select | Q3: ▼ Enter | R3: ▼ Enter | S3: ▼ Enter | T3: ▼ Enter | U3: ▼ Enter | V3: ◀ Auto | W3: ◀ Auto | X3: ◀ Auto | Y3: ◀ Auto | Z3: ◀ Auto | AA3: ◀ Auto | AB3: ◀ Auto
A4: Jones, Bhrett | B4: 2-2103 | C4: A4 | D4: 46092 | E4: =IF(D4="","",D4-90) -> 46002 | F4: =IF(D4="","",D4-60) -> 46032 | G4: =IF(D4="","",D4-30) -> 46062 | H4: 0 | I4: 1422 | J4: =IF(I4="","",IF(ABS(N4-W4)<=ABS(M4-W4),IF(ABS(N4-W4)<=ABS(O4-W4),"Offer 2","Offer 3"),IF(ABS(M4-W4)<=ABS(O4-W4),"Offer 1","Offer 3"))) -> Offer 1 | K4: 0 | L4: =IF(OR(I4="",K4=""),"",CEILING(I4*(1+K4),5)) -> 1425 | M4: =IF(I4="","",IF(X4="Under",CEILING(MAX(I4*1.02,MIN(V4,W4)*0.95),5),CEILING(MAX(I4*1.03,MIN(V4,W4)*0.97),5))) -> 1465 | N4: =IF(I4="","",IF(X4="Under",CEILING(MAX(I4*1.03,(V4+W4)/2*0.96),5),CEILING(MAX(I4*1.05,(V4+W4)/2*0.98),5))) -> 1495 | O4: =IF(I4="","",IF(X4="Under",CEILING(MAX(I4*1.05,MIN(V4,W4*1.01)),5),CEILING(MAX(I4*1.08,MIN(V4,W4*1.02)),5))) -> 1540 | P4: Investor Override | Q4: 46030 | T4: (904) 788-3770 | U4: 12 months / 0% increase / $250 concession | V4: =IF(C4="","",IFERROR(VLOOKUP(C4,SETUP!$A$9:$D$24,2,0),"⚠ Check SETUP")) -> 1421 | W4: =IF(C4="","",IFERROR(VLOOKUP(C4,SETUP!$A$9:$D$24,3,0),"⚠ Check SETUP")) -> 1424 | X4: =IF(C4="","",IFERROR(VLOOKUP(C4,SETUP!$A$9:$D$24,4,0),"⚠ Check SETUP")) -> Over | Y4: =IF(OR(I4="",M4=""),"",(M4-I4)/I4) -> 0.0302391 | Z4: =IF(OR(I4="",N4=""),"",(N4-I4)/I4) -> 0.051336146 | AA4: =IF(OR(I4="",O4=""),"",(O4-I4)/I4) -> 0.082981716 | AB4: =IF(OR(Q4="",S4<>"",P4="",I4=""),"",IF(P4="Investor Override",IF(L4="","",(L4-I4)/I4),IF(P4="Offer 1",IF(M4="","",(M4-I4)/I4),IF(P4="Offer 2",IF(N4="","",(N4-I4)/I4),IF(P4="Offer 3",IF(O4="","",(O4-I4)/I4),""))))) -> 0.0021097046
A5: Maslennikov, George | B5: 2-2405 | C5: A4 | D5: 46094 | E5: =IF(D5="","",D5-90) -> 46004 | F5: =IF(D5="","",D5-60) -> 46034 | G5: =IF(D5="","",D5-30) -> 46064 | H5: 0 | I5: 1488 | J5: =IF(I5="","",IF(ABS(N5-W5)<=ABS(M5-W5),IF(ABS(N5-W5)<=ABS(O5-W5),"Offer 2","Offer 3"),IF(ABS(M5-W5)<=ABS(O5-W5),"Offer 1","Offer 3"))) -> Offer 1 | K5: 0 | L5: =IF(OR(I5="",K5=""),"",CEILING(I5*(1+K5),5)) -> 1490 | M5: =IF(I5="","",IF(X5="Under",CEILING(MAX(I5*1.02,MIN(V5,W5)*0.95),5),CEILING(MAX(I5*1.03,MIN(V5,W5)*0.97),5))) -> 1535 | N5: =IF(I5="","",IF(X5="Under",CEILING(MAX(I5*1.03,(V5+W5)/2*0.96),5),CEILING(MAX(I5*1.05,(V5+W5)/2*0.98),5))) -> 1565 | O5: =IF(I5="","",IF(X5="Under",CEILING(MAX(I5*1.05,MIN(V5,W5*1.01)),5),CEILING(MAX(I5*1.08,MIN(V5,W5*1.02)),5))) -> 1610 | P5: Investor Override | Q5: 46055 | T5: (770) 877-2171 | U5: 12 months / 0% increase / $250 concession | V5: =IF(C5="","",IFERROR(VLOOKUP(C5,SETUP!$A$9:$D$24,2,0),"⚠ Check SETUP")) -> 1421 | W5: =IF(C5="","",IFERROR(VLOOKUP(C5,SETUP!$A$9:$D$24,3,0),"⚠ Check SETUP")) -> 1424 | X5: =IF(C5="","",IFERROR(VLOOKUP(C5,SETUP!$A$9:$D$24,4,0),"⚠ Check SETUP")) -> Over | Y5: =IF(OR(I5="",M5=""),"",(M5-I5)/I5) -> 0.031586022 | Z5: =IF(OR(I5="",N5=""),"",(N5-I5)/I5) -> 0.051747312 | AA5: =IF(OR(I5="",O5=""),"",(O5-I5)/I5) -> 0.081989247 | AB5: =IF(OR(Q5="",S5<>"",P5="",I5=""),"",IF(P5="Investor Override",IF(L5="","",(L5-I5)/I5),IF(P5="Offer 1",IF(M5="","",(M5-I5)/I5),IF(P5="Offer 2",IF(N5="","",(N5-I5)/I5),IF(P5="Offer 3",IF(O5="","",(O5-I5)/I5),""))))) -> 0.001344086
A6: Meador, Camden | B6: 3-3302 | C6: B5 | D6: 46095 | E6: =IF(D6="","",D6-90) -> 46005 | F6: =IF(D6="","",D6-60) -> 46035 | G6: =IF(D6="","",D6-30) -> 46065 | H6: 0 | I6: 1839 | J6: =IF(I6="","",IF(ABS(N6-W6)<=ABS(M6-W6),IF(ABS(N6-W6)<=ABS(O6-W6),"Offer 2","Offer 3"),IF(ABS(M6-W6)<=ABS(O6-W6),"Offer 1","Offer 3"))) -> Offer 1 | K6: 0 | L6: =IF(OR(I6="",K6=""),"",CEILING(I6*(1+K6),5)) -> 1840 | M6: =IF(I6="","",IF(X6="Under",CEILING(MAX(I6*1.02,MIN(V6,W6)*0.95),5),CEILING(MAX(I6*1.03,MIN(V6,W6)*0.97),5))) -> 1895 | N6: =IF(I6="","",IF(X6="Under",CEILING(MAX(I6*1.03,(V6+W6)/2*0.96),5),CEILING(MAX(I6*1.05,(V6+W6)/2*0.98),5))) -> 1935 | O6: =IF(I6="","",IF(X6="Under",CEILING(MAX(I6*1.05,MIN(V6,W6*1.01)),5),CEILING(MAX(I6*1.08,MIN(V6,W6*1.02)),5))) -> 1990 | P6: Investor Override | Q6: 46071 | T6: (615) 200-4957 | U6: 15 months / 0% increase / No concession | V6: =IF(C6="","",IFERROR(VLOOKUP(C6,SETUP!$A$9:$D$24,2,0),"⚠ Check SETUP")) -> 1860 | W6: =IF(C6="","",IFERROR(VLOOKUP(C6,SETUP!$A$9:$D$24,3,0),"⚠ Check SETUP")) -> 1776 | X6: =IF(C6="","",IFERROR(VLOOKUP(C6,SETUP!$A$9:$D$24,4,0),"⚠ Check SETUP")) -> Over | Y6: =IF(OR(I6="",M6=""),"",(M6-I6)/I6) -> 0.030451332 | Z6: =IF(OR(I6="",N6=""),"",(N6-I6)/I6) -> 0.052202284 | AA6: =IF(OR(I6="",O6=""),"",(O6-I6)/I6) -> 0.082109842 | AB6: =IF(OR(Q6="",S6<>"",P6="",I6=""),"",IF(P6="Investor Override",IF(L6="","",(L6-I6)/I6),IF(P6="Offer 1",IF(M6="","",(M6-I6)/I6),IF(P6="Offer 2",IF(N6="","",(N6-I6)/I6),IF(P6="Offer 3",IF(O6="","",(O6-I6)/I6),""))))) -> 0.00054377379
A7: Isenbeck, Eric | B7: 1-1415 | C7: A4 | D7: 46097 | E7: =IF(D7="","",D7-90) -> 46007 | F7: =IF(D7="","",D7-60) -> 46037 | G7: =IF(D7="","",D7-30) -> 46067 | H7: 1595 | I7: 1595 | J7: =IF(I7="","",IF(ABS(N7-W7)<=ABS(M7-W7),IF(ABS(N7-W7)<=ABS(O7-W7),"Offer 2","Offer 3"),IF(ABS(M7-W7)<=ABS(O7-W7),"Offer 1","Offer 3"))) -> Offer 1 | K7: 0.016 | L7: =IF(OR(I7="",K7=""),"",CEILING(I7*(1+K7),5)) -> 1625 | M7: =IF(I7="","",IF(X7="Under",CEILING(MAX(I7*1.02,MIN(V7,W7)*0.95),5),CEILING(MAX(I7*1.03,MIN(V7,W7)*0.97),5))) -> 1645 | N7: =IF(I7="","",IF(X7="Under",CEILING(MAX(I7*1.03,(V7+W7)/2*0.96),5),CEILING(MAX(I7*1.05,(V7+W7)/2*0.98),5))) -> 1675 | O7: =IF(I7="","",IF(X7="Under",CEILING(MAX(I7*1.05,MIN(V7,W7*1.01)),5),CEILING(MAX(I7*1.08,MIN(V7,W7*1.02)),5))) -> 1725 | P7: Investor Override | Q7: 46045 | T7: (813) 388-1477 | U7: 14 months / 2% increase / $250 concession | V7: =IF(C7="","",IFERROR(VLOOKUP(C7,SETUP!$A$9:$D$24,2,0),"⚠ Check SETUP")) -> 1421 | W7: =IF(C7="","",IFERROR(VLOOKUP(C7,SETUP!$A$9:$D$24,3,0),"⚠ Check SETUP")) -> 1424 | X7: =IF(C7="","",IFERROR(VLOOKUP(C7,SETUP!$A$9:$D$24,4,0),"⚠ Check SETUP")) -> Over | Y7: =IF(OR(I7="",M7=""),"",(M7-I7)/I7) -> 0.031347962 | Z7: =IF(OR(I7="",N7=""),"",(N7-I7)/I7) -> 0.05015674 | AA7: =IF(OR(I7="",O7=""),"",(O7-I7)/I7) -> 0.081504702 | AB7: =IF(OR(Q7="",S7<>"",P7="",I7=""),"",IF(P7="Investor Override",IF(L7="","",(L7-I7)/I7),IF(P7="Offer 1",IF(M7="","",(M7-I7)/I7),IF(P7="Offer 2",IF(N7="","",(N7-I7)/I7),IF(P7="Offer 3",IF(O7="","",(O7-I7)/I7),""))))) -> 0.018808777
A8: Contreras, Alfonso | B8: 2-2132 | C8: B3 | D8: 46097 | E8: =IF(D8="","",D8-90) -> 46007 | F8: =IF(D8="","",D8-60) -> 46037 | G8: =IF(D8="","",D8-30) -> 46067 | H8: 0 | I8: 1934 | J8: =IF(I8="","",IF(ABS(N8-W8)<=ABS(M8-W8),IF(ABS(N8-W8)<=ABS(O8-W8),"Offer 2","Offer 3"),IF(ABS(M8-W8)<=ABS(O8-W8),"Offer 1","Offer 3"))) -> Offer 1 | K8: 0 | L8: =IF(OR(I8="",K8=""),"",CEILING(I8*(1+K8),5)) -> 1935 | M8: =IF(I8="","",IF(X8="Under",CEILING(MAX(I8*1.02,MIN(V8,W8)*0.95),5),CEILING(MAX(I8*1.03,MIN(V8,W8)*0.97),5))) -> 1975 | N8: =IF(I8="","",IF(X8="Under",CEILING(MAX(I8*1.03,(V8+W8)/2*0.96),5),CEILING(MAX(I8*1.05,(V8+W8)/2*0.98),5))) -> 1995 | O8: =IF(I8="","",IF(X8="Under",CEILING(MAX(I8*1.05,MIN(V8,W8*1.01)),5),CEILING(MAX(I8*1.08,MIN(V8,W8*1.02)),5))) -> 2035 | P8: Investor Override | Q8: 46055 | T8: (305) 332-5594 | U8: 15 months / 0% increase / $250 concession | V8: =IF(C8="","",IFERROR(VLOOKUP(C8,SETUP!$A$9:$D$24,2,0),"⚠ Check SETUP")) -> 1880 | W8: =IF(C8="","",IFERROR(VLOOKUP(C8,SETUP!$A$9:$D$24,3,0),"⚠ Check SETUP")) -> 1976 | X8: =IF(C8="","",IFERROR(VLOOKUP(C8,SETUP!$A$9:$D$24,4,0),"⚠ Check SETUP")) -> Under | Y8: =IF(OR(I8="",M8=""),"",(M8-I8)/I8) -> 0.021199586 | Z8: =IF(OR(I8="",N8=""),"",(N8-I8)/I8) -> 0.031540848 | AA8: =IF(OR(I8="",O8=""),"",(O8-I8)/I8) -> 0.052223371 | AB8: =IF(OR(Q8="",S8<>"",P8="",I8=""),"",IF(P8="Investor Override",IF(L8="","",(L8-I8)/I8),IF(P8="Offer 1",IF(M8="","",(M8-I8)/I8),IF(P8="Offer 2",IF(N8="","",(N8-I8)/I8),IF(P8="Offer 3",IF(O8="","",(O8-I8)/I8),""))))) -> 0.00051706308
A9: Harper, Elise | B9: 3-3205 | C9: A1 | D9: 46100 | E9: =IF(D9="","",D9-90) -> 46010 | F9: =IF(D9="","",D9-60) -> 46040 | G9: =IF(D9="","",D9-30) -> 46070 | H9: 1497 | I9: 1497 | J9: =IF(I9="","",IF(ABS(N9-W9)<=ABS(M9-W9),IF(ABS(N9-W9)<=ABS(O9-W9),"Offer 2","Offer 3"),IF(ABS(M9-W9)<=ABS(O9-W9),"Offer 1","Offer 3"))) -> Offer 1 | K9: 0.023 | L9: =IF(OR(I9="",K9=""),"",CEILING(I9*(1+K9),5)) -> 1535 | M9: =IF(I9="","",IF(X9="Under",CEILING(MAX(I9*1.02,MIN(V9,W9)*0.95),5),CEILING(MAX(I9*1.03,MIN(V9,W9)*0.97),5))) -> 1530 | N9: =IF(I9="","",IF(X9="Under",CEILING(MAX(I9*1.03,(V9+W9)/2*0.96),5),CEILING(MAX(I9*1.05,(V9+W9)/2*0.98),5))) -> 1545 | O9: =IF(I9="","",IF(X9="Under",CEILING(MAX(I9*1.05,MIN(V9,W9*1.01)),5),CEILING(MAX(I9*1.08,MIN(V9,W9*1.02)),5))) -> 1575 | P9: Investor Override | Q9: 46062 | T9: (904) 770-0706 | U9: 14 months / 2% increase / No concession | V9: =IF(C9="","",IFERROR(VLOOKUP(C9,SETUP!$A$9:$D$24,2,0),"⚠ Check SETUP")) -> 1595 | W9: =IF(C9="","",IFERROR(VLOOKUP(C9,SETUP!$A$9:$D$24,3,0),"⚠ Check SETUP")) -> 1504 | X9: =IF(C9="","",IFERROR(VLOOKUP(C9,SETUP!$A$9:$D$24,4,0),"⚠ Check SETUP")) -> Under | Y9: =IF(OR(I9="",M9=""),"",(M9-I9)/I9) -> 0.022044088 | Z9: =IF(OR(I9="",N9=""),"",(N9-I9)/I9) -> 0.032064128 | AA9: =IF(OR(I9="",O9=""),"",(O9-I9)/I9) -> 0.052104208 | AB9: =IF(OR(Q9="",S9<>"",P9="",I9=""),"",IF(P9="Investor Override",IF(L9="","",(L9-I9)/I9),IF(P9="Offer 1",IF(M9="","",(M9-I9)/I9),IF(P9="Offer 2",IF(N9="","",(N9-I9)/I9),IF(P9="Offer 3",IF(O9="","",(O9-I9)/I9),""))))) -> 0.025384102
A10: Crowley Sr, Chris | B10: 3-3105 | C10: A1 | D10: 46100 | E10: =IF(D10="","",D10-90) -> 46010 | F10: =IF(D10="","",D10-60) -> 46040 | G10: =IF(D10="","",D10-30) -> 46070 | H10: 0 | I10: 1473 | J10: =IF(I10="","",IF(ABS(N10-W10)<=ABS(M10-W10),IF(ABS(N10-W10)<=ABS(O10-W10),"Offer 2","Offer 3"),IF(ABS(M10-W10)<=ABS(O10-W10),"Offer 1","Offer 3"))) -> Offer 1 | K10: 0.02 | L10: =IF(OR(I10="",K10=""),"",CEILING(I10*(1+K10),5)) -> 1505 | M10: =IF(I10="","",IF(X10="Under",CEILING(MAX(I10*1.02,MIN(V10,W10)*0.95),5),CEILING(MAX(I10*1.03,MIN(V10,W10)*0.97),5))) -> 1505 | N10: =IF(I10="","",IF(X10="Under",CEILING(MAX(I10*1.03,(V10+W10)/2*0.96),5),CEILING(MAX(I10*1.05,(V10+W10)/2*0.98),5))) -> 1520 | O10: =IF(I10="","",IF(X10="Under",CEILING(MAX(I10*1.05,MIN(V10,W10*1.01)),5),CEILING(MAX(I10*1.08,MIN(V10,W10*1.02)),5))) -> 1550 | S10: 46038 | T10: (609) 554-9142 | U10: Condo purchase | V10: =IF(C10="","",IFERROR(VLOOKUP(C10,SETUP!$A$9:$D$24,2,0),"⚠ Check SETUP")) -> 1595 | W10: =IF(C10="","",IFERROR(VLOOKUP(C10,SETUP!$A$9:$D$24,3,0),"⚠ Check SETUP")) -> 1504 | X10: =IF(C10="","",IFERROR(VLOOKUP(C10,SETUP!$A$9:$D$24,4,0),"⚠ Check SETUP")) -> Under | Y10: =IF(OR(I10="",M10=""),"",(M10-I10)/I10) -> 0.021724372 | Z10: =IF(OR(I10="",N10=""),"",(N10-I10)/I10) -> 0.031907671 | AA10: =IF(OR(I10="",O10=""),"",(O10-I10)/I10) -> 0.05227427 | AB10: =IF(OR(Q10="",S10<>"",P10="",I10=""),"",IF(P10="Investor Override",IF(L10="","",(L10-I10)/I10),IF(P10="Offer 1",IF(M10="","",(M10-I10)/I10),IF(P10="Offer 2",IF(N10="","",(N10-I10)/I10),IF(P10="Offer 3",IF(O10="","",(O10-I10)/I10),"")))))
A11: Clement, Justin | B11: 1-1418 | C11: A1 | D11: 46101 | E11: =IF(D11="","",D11-90) -> 46011 | F11: =IF(D11="","",D11-60) -> 46041 | G11: =IF(D11="","",D11-30) -> 46071 | H11: 0 | I11: 1561 | J11: =IF(I11="","",IF(ABS(N11-W11)<=ABS(M11-W11),IF(ABS(N11-W11)<=ABS(O11-W11),"Offer 2","Offer 3"),IF(ABS(M11-W11)<=ABS(O11-W11),"Offer 1","Offer 3"))) -> Offer 1 | K11: 0.02 | L11: =IF(OR(I11="",K11=""),"",CEILING(I11*(1+K11),5)) -> 1595 | M11: =IF(I11="","",IF(X11="Under",CEILING(MAX(I11*1.02,MIN(V11,W11)*0.95),5),CEILING(MAX(I11*1.03,MIN(V11,W11)*0.97),5))) -> 1595 | N11: =IF(I11="","",IF(X11="Under",CEILING(MAX(I11*1.03,(V11+W11)/2*0.96),5),CEILING(MAX(I11*1.05,(V11+W11)/2*0.98),5))) -> 1610 | O11: =IF(I11="","",IF(X11="Under",CEILING(MAX(I11*1.05,MIN(V11,W11*1.01)),5),CEILING(MAX(I11*1.08,MIN(V11,W11*1.02)),5))) -> 1640 | S11: 46022 | T11: (409) 781-5300 | U11: Refused feedback - Gave SJC PO Box at MO | V11: =IF(C11="","",IFERROR(VLOOKUP(C11,SETUP!$A$9:$D$24,2,0),"⚠ Check SETUP")) -> 1595 | W11: =IF(C11="","",IFERROR(VLOOKUP(C11,SETUP!$A$9:$D$24,3,0),"⚠ Check SETUP")) -> 1504 | X11: =IF(C11="","",IFERROR(VLOOKUP(C11,SETUP!$A$9:$D$24,4,0),"⚠ Check SETUP")) -> Under | Y11: =IF(OR(I11="",M11=""),"",(M11-I11)/I11) -> 0.02178091 | Z11: =IF(OR(I11="",N11=""),"",(N11-I11)/I11) -> 0.031390135 | AA11: =IF(OR(I11="",O11=""),"",(O11-I11)/I11) -> 0.050608584 | AB11: =IF(OR(Q11="",S11<>"",P11="",I11=""),"",IF(P11="Investor Override",IF(L11="","",(L11-I11)/I11),IF(P11="Offer 1",IF(M11="","",(M11-I11)/I11),IF(P11="Offer 2",IF(N11="","",(N11-I11)/I11),IF(P11="Offer 3",IF(O11="","",(O11-I11)/I11),"")))))
A12: Leveson, Madelyne | B12: 3-3107 | C12: A5 | D12: 46101 | E12: =IF(D12="","",D12-90) -> 46011 | F12: =IF(D12="","",D12-60) -> 46041 | G12: =IF(D12="","",D12-30) -> 46071 | H12: 1540 | I12: 1540 | J12: =IF(I12="","",IF(ABS(N12-W12)<=ABS(M12-W12),IF(ABS(N12-W12)<=ABS(O12-W12),"Offer 2","Offer 3"),IF(ABS(M12-W12)<=ABS(O12-W12),"Offer 1","Offer 3"))) -> Offer 1 | K12: 0.02 | L12: =IF(OR(I12="",K12=""),"",CEILING(I12*(1+K12),5)) -> 1575 | M12: =IF(I12="","",IF(X12="Under",CEILING(MAX(I12*1.02,MIN(V12,W12)*0.95),5),CEILING(MAX(I12*1.03,MIN(V12,W12)*0.97),5))) -> 1575 | N12: =IF(I12="","",IF(X12="Under",CEILING(MAX(I12*1.03,(V12+W12)/2*0.96),5),CEILING(MAX(I12*1.05,(V12+W12)/2*0.98),5))) -> 1590 | O12: =IF(I12="","",IF(X12="Under",CEILING(MAX(I12*1.05,MIN(V12,W12*1.01)),5),CEILING(MAX(I12*1.08,MIN(V12,W12*1.02)),5))) -> 1620 | S12: 46036 | T12: (813) 610-0948 | U12: Relocated out of state | V12: =IF(C12="","",IFERROR(VLOOKUP(C12,SETUP!$A$9:$D$24,2,0),"⚠ Check SETUP")) -> 1719 | W12: =IF(C12="","",IFERROR(VLOOKUP(C12,SETUP!$A$9:$D$24,3,0),"⚠ Check SETUP")) -> 1561 | X12: =IF(C12="","",IFERROR(VLOOKUP(C12,SETUP!$A$9:$D$24,4,0),"⚠ Check SETUP")) -> Under | Y12: =IF(OR(I12="",M12=""),"",(M12-I12)/I12) -> 0.022727273 | Z12: =IF(OR(I12="",N12=""),"",(N12-I12)/I12) -> 0.032467532 | AA12: =IF(OR(I12="",O12=""),"",(O12-I12)/I12) -> 0.051948052 | AB12: =IF(OR(Q12="",S12<>"",P12="",I12=""),"",IF(P12="Investor Override",IF(L12="","",(L12-I12)/I12),IF(P12="Offer 1",IF(M12="","",(M12-I12)/I12),IF(P12="Offer 2",IF(N12="","",(N12-I12)/I12),IF(P12="Offer 3",IF(O12="","",(O12-I12)/I12),"")))))
A13: Morris, Kortney | B13: 1-1426 | C13: A4 | D13: 46102 | E13: =IF(D13="","",D13-90) -> 46012 | F13: =IF(D13="","",D13-60) -> 46042 | G13: =IF(D13="","",D13-30) -> 46072 | H13: 1595 | I13: 1625 | J13: =IF(I13="","",IF(ABS(N13-W13)<=ABS(M13-W13),IF(ABS(N13-W13)<=ABS(O13-W13),"Offer 2","Offer 3"),IF(ABS(M13-W13)<=ABS(O13-W13),"Offer 1","Offer 3"))) -> Offer 1 | K13: 0.016 | L13: =IF(OR(I13="",K13=""),"",CEILING(I13*(1+K13),5)) -> 1655 | M13: =IF(I13="","",IF(X13="Under",CEILING(MAX(I13*1.02,MIN(V13,W13)*0.95),5),CEILING(MAX(I13*1.03,MIN(V13,W13)*0.97),5))) -> 1675 | N13: =IF(I13="","",IF(X13="Under",CEILING(MAX(I13*1.03,(V13+W13)/2*0.96),5),CEILING(MAX(I13*1.05,(V13+W13)/2*0.98),5))) -> 1710 | O13: =IF(I13="","",IF(X13="Under",CEILING(MAX(I13*1.05,MIN(V13,W13*1.01)),5),CEILING(MAX(I13*1.08,MIN(V13,W13*1.02)),5))) -> 1755 | P13: Investor Override | Q13: 46002 | T13: (314) 922-0090 | U13: 15 month / 2% increase / $250 concession | V13: =IF(C13="","",IFERROR(VLOOKUP(C13,SETUP!$A$9:$D$24,2,0),"⚠ Check SETUP")) -> 1421 | W13: =IF(C13="","",IFERROR(VLOOKUP(C13,SETUP!$A$9:$D$24,3,0),"⚠ Check SETUP")) -> 1424 | X13: =IF(C13="","",IFERROR(VLOOKUP(C13,SETUP!$A$9:$D$24,4,0),"⚠ Check SETUP")) -> Over | Y13: =IF(OR(I13="",M13=""),"",(M13-I13)/I13) -> 0.030769231 | Z13: =IF(OR(I13="",N13=""),"",(N13-I13)/I13) -> 0.052307692 | AA13: =IF(OR(I13="",O13=""),"",(O13-I13)/I13) -> 0.08 | AB13: =IF(OR(Q13="",S13<>"",P13="",I13=""),"",IF(P13="Investor Override",IF(L13="","",(L13-I13)/I13),IF(P13="Offer 1",IF(M13="","",(M13-I13)/I13),IF(P13="Offer 2",IF(N13="","",(N13-I13)/I13),IF(P13="Offer 3",IF(O13="","",(O13-I13)/I13),""))))) -> 0.018461538
A14: Murdock, John | B14: 2-2421 | C14: B1 | D14: 46108 | E14: =IF(D14="","",D14-90) -> 46018 | F14: =IF(D14="","",D14-60) -> 46048 | G14: =IF(D14="","",D14-30) -> 46078 | H14: 0 | I14: 1798 | J14: =IF(I14="","",IF(ABS(N14-W14)<=ABS(M14-W14),IF(ABS(N14-W14)<=ABS(O14-W14),"Offer 2","Offer 3"),IF(ABS(M14-W14)<=ABS(O14-W14),"Offer 1","Offer 3"))) -> Offer 1 | K14: 0 | L14: =IF(OR(I14="",K14=""),"",CEILING(I14*(1+K14),5)) -> 1800 | M14: =IF(I14="","",IF(X14="Under",CEILING(MAX(I14*1.02,MIN(V14,W14)*0.95),5),CEILING(MAX(I14*1.03,MIN(V14,W14)*0.97),5))) -> 1835 | N14: =IF(I14="","",IF(X14="Under",CEILING(MAX(I14*1.03,(V14+W14)/2*0.96),5),CEILING(MAX(I14*1.05,(V14+W14)/2*0.98),5))) -> 1855 | O14: =IF(I14="","",IF(X14="Under",CEILING(MAX(I14*1.05,MIN(V14,W14*1.01)),5),CEILING(MAX(I14*1.08,MIN(V14,W14*1.02)),5))) -> 1890 | S14: 46048 | T14: (813) 469-6465 | U14: Home purchase | V14: =IF(C14="","",IFERROR(VLOOKUP(C14,SETUP!$A$9:$D$24,2,0),"⚠ Check SETUP")) -> 1809 | W14: =IF(C14="","",IFERROR(VLOOKUP(C14,SETUP!$A$9:$D$24,3,0),"⚠ Check SETUP")) -> 1764 | X14: =IF(C14="","",IFERROR(VLOOKUP(C14,SETUP!$A$9:$D$24,4,0),"⚠ Check SETUP")) -> Under | Y14: =IF(OR(I14="",M14=""),"",(M14-I14)/I14) -> 0.02057842 | Z14: =IF(OR(I14="",N14=""),"",(N14-I14)/I14) -> 0.031701891 | AA14: =IF(OR(I14="",O14=""),"",(O14-I14)/I14) -> 0.051167964 | AB14: =IF(OR(Q14="",S14<>"",P14="",I14=""),"",IF(P14="Investor Override",IF(L14="","",(L14-I14)/I14),IF(P14="Offer 1",IF(M14="","",(M14-I14)/I14),IF(P14="Offer 2",IF(N14="","",(N14-I14)/I14),IF(P14="Offer 3",IF(O14="","",(O14-I14)/I14),"")))))
A15: Beardsley, Aaron | B15: 1-1419 | C15: B2 | D15: 46108 | E15: =IF(D15="","",D15-90) -> 46018 | F15: =IF(D15="","",D15-60) -> 46048 | G15: =IF(D15="","",D15-30) -> 46078 | H15: 0 | I15: 1911 | J15: =IF(I15="","",IF(ABS(N15-W15)<=ABS(M15-W15),IF(ABS(N15-W15)<=ABS(O15-W15),"Offer 2","Offer 3"),IF(ABS(M15-W15)<=ABS(O15-W15),"Offer 1","Offer 3"))) -> Offer 1 | K15: 0 | L15: =IF(OR(I15="",K15=""),"",CEILING(I15*(1+K15),5)) -> 1915 | M15: =IF(I15="","",IF(X15="Under",CEILING(MAX(I15*1.02,MIN(V15,W15)*0.95),5),CEILING(MAX(I15*1.03,MIN(V15,W15)*0.97),5))) -> 1950 | N15: =IF(I15="","",IF(X15="Under",CEILING(MAX(I15*1.03,(V15+W15)/2*0.96),5),CEILING(MAX(I15*1.05,(V15+W15)/2*0.98),5))) -> 1970 | O15: =IF(I15="","",IF(X15="Under",CEILING(MAX(I15*1.05,MIN(V15,W15*1.01)),5),CEILING(MAX(I15*1.08,MIN(V15,W15*1.02)),5))) -> 2010 | P15: Investor Override | Q15: 46031 | T15: (704) 287-9074 | U15: 12 months / 0% increase / $250 concession | V15: =IF(C15="","",IFERROR(VLOOKUP(C15,SETUP!$A$9:$D$24,2,0),"⚠ Check SETUP")) -> 1595 | W15: =IF(C15="","",IFERROR(VLOOKUP(C15,SETUP!$A$9:$D$24,3,0),"⚠ Check SETUP")) -> 1806 | X15: =IF(C15="","",IFERROR(VLOOKUP(C15,SETUP!$A$9:$D$24,4,0),"⚠ Check SETUP")) -> Under | Y15: =IF(OR(I15="",M15=""),"",(M15-I15)/I15) -> 0.020408163 | Z15: =IF(OR(I15="",N15=""),"",(N15-I15)/I15) -> 0.030873888 | AA15: =IF(OR(I15="",O15=""),"",(O15-I15)/I15) -> 0.051805338 | AB15: =IF(OR(Q15="",S15<>"",P15="",I15=""),"",IF(P15="Investor Override",IF(L15="","",(L15-I15)/I15),IF(P15="Offer 1",IF(M15="","",(M15-I15)/I15),IF(P15="Offer 2",IF(N15="","",(N15-I15)/I15),IF(P15="Offer 3",IF(O15="","",(O15-I15)/I15),""))))) -> 0.002093145
A16: Fussell, Callie | B16: 1-1407 | C16: A1 | D16: 46111 | E16: =IF(D16="","",D16-90) -> 46021 | F16: =IF(D16="","",D16-60) -> 46051 | G16: =IF(D16="","",D16-30) -> 46081 | H16: 0 | I16: 1494 | J16: =IF(I16="","",IF(ABS(N16-W16)<=ABS(M16-W16),IF(ABS(N16-W16)<=ABS(O16-W16),"Offer 2","Offer 3"),IF(ABS(M16-W16)<=ABS(O16-W16),"Offer 1","Offer 3"))) -> Offer 1 | K16: 0.04 | L16: =IF(OR(I16="",K16=""),"",CEILING(I16*(1+K16),5)) -> 1555 | M16: =IF(I16="","",IF(X16="Under",CEILING(MAX(I16*1.02,MIN(V16,W16)*0.95),5),CEILING(MAX(I16*1.03,MIN(V16,W16)*0.97),5))) -> 1525 | N16: =IF(I16="","",IF(X16="Under",CEILING(MAX(I16*1.03,(V16+W16)/2*0.96),5),CEILING(MAX(I16*1.05,(V16+W16)/2*0.98),5))) -> 1540 | O16: =IF(I16="","",IF(X16="Under",CEILING(MAX(I16*1.05,MIN(V16,W16*1.01)),5),CEILING(MAX(I16*1.08,MIN(V16,W16*1.02)),5))) -> 1570 | R16: 46109 | T16: (904) 827-3893 | U16: Larger apartment | V16: =IF(C16="","",IFERROR(VLOOKUP(C16,SETUP!$A$9:$D$24,2,0),"⚠ Check SETUP")) -> 1595 | W16: =IF(C16="","",IFERROR(VLOOKUP(C16,SETUP!$A$9:$D$24,3,0),"⚠ Check SETUP")) -> 1504 | X16: =IF(C16="","",IFERROR(VLOOKUP(C16,SETUP!$A$9:$D$24,4,0),"⚠ Check SETUP")) -> Under | Y16: =IF(OR(I16="",M16=""),"",(M16-I16)/I16) -> 0.020749665 | Z16: =IF(OR(I16="",N16=""),"",(N16-I16)/I16) -> 0.030789826 | AA16: =IF(OR(I16="",O16=""),"",(O16-I16)/I16) -> 0.050870147 | AB16: =IF(OR(Q16="",S16<>"",P16="",I16=""),"",IF(P16="Investor Override",IF(L16="","",(L16-I16)/I16),IF(P16="Offer 1",IF(M16="","",(M16-I16)/I16),IF(P16="Offer 2",IF(N16="","",(N16-I16)/I16),IF(P16="Offer 3",IF(O16="","",(O16-I16)/I16),"")))))
A18: RETENTION ANALYSIS
A19: Metric | B19: Count | C19: % of Expirations | D19: % of Decided | E19: Status
A20: Total Lease Expirations | B20: =COUNTA(A4:A16) -> 13
A21: Renewals Signed | B21: =COUNTA(Q4:Q16) -> 8 | C21: =IFERROR(B21/B20,"-") -> 0.61538462 | D21: =IFERROR(B21/(B21+B22),"-") -> 0.66666667 | E21: =IF(B20=0,"Awaiting data",IF(B21/B20>=0.6,"On Track ✓","Needs Attention ⚠")) -> On Track ✓
A22: NTV's Received | B22: =COUNTA(S4:S16) -> 4 | C22: =IFERROR(B22/B20,"-") -> 0.30769231 | D22: =IFERROR(B22/(B21+B22),"-") -> 0.33333333 | E22: =IF(B20=0,"Awaiting data",IF(B22/B20<=0.2,"Acceptable","High NTV ⚠")) -> High NTV ⚠
A23: Transfers | B23: =COUNTA(R4:R16) -> 1 | C23: =IFERROR(B23/B20,"-") -> 0.076923077 | D23: — | E23: Resident retained in portfolio
A24: Pending / Not Yet Decided | B24: =MAX(0,B20-B21-B22-B23) -> 0 | C24: =IFERROR(B24/B20,"-") -> 0 | D24: — | E24: =IF(B24=0,"All accounted for ✓","Follow up needed") -> All accounted for ✓
A26: RETENTION RATE (Renewals ÷ Total Expirations) | C26: =IFERROR(B21/B20,"-") -> 0.61538462 | D26: =IF(B20=0,"Enter resident data to calculate",IF(B21/B20>=0.6,"✓ Meeting target retention","⚠ Below target — review offers")) -> ✓ Meeting target retention
A27: RETENTION RATE (Renewals ÷ Renewals + NTVs) ← of decided residents | C27: =IFERROR(B21/(B21+B22),"-") -> 0.66666667 | D27: Excludes pending residents — only counts those who have made a decision (renewed or NTV'd)
A30: Legend
A31: Renewed (auto: enter date in Renewal Signed)
A32: Pending Signature (manual: apply yellow fill)
A33: NTV / Notice to Vacate (auto: enter date in NTV Rcv'd)
A34: Transfer (auto: enter date in Transfer)
A35: MTM / Month-to-Month (manual: apply gray fill)

Sheet April 2026
A1: =SETUP!B3&" - "&SETUP!B4&" Renewals" -> RISE Bartram Park - April 2026 Renewals
A2: Name | B2: Unit | C2: Unit Type | D2: Expiration Date | E2: 90-Day Notice | F2: 60-Day Notice | G2: 30-Day Notice | H2: Deposit Held | I2: Current Rate | J2: Recommended Offer | K2: Investor Override % Increase | L2: Investor Override Offer | M2: Offer 1 Conservative | N2: Offer 2 Balanced | O2: Offer 3 Aggressive | P2: Signed Offer | Q2: Renewal Signed | R2: Transfer | S2: NTV Rcv'd | T2: Phone | U2: Notes | V2: Market Rate | W2: Budget | X2: Occupancy (Under/Over) | Y2: Rent Growth Offer 1 | Z2: Rent Growth Offer 2 | AA2: Rent Growth Offer 3 | AB2: Signed Rent Growth
A3: ▼ Enter | B3: ▼ Enter | C3: ▼ Enter | D3: ▼ Enter | E3: ◀ Auto | F3: ◀ Auto | G3: ◀ Auto | H3: ▼ Enter | I3: ▼ Enter | J3: ◀ Auto | K3: ▼ Enter | L3: ◀ Auto | M3: ◀ Auto | N3: ◀ Auto | O3: ◀ Auto | P3: ▼ Select | Q3: ▼ Enter | R3: ▼ Enter | S3: ▼ Enter | T3: ▼ Enter | U3: ▼ Enter | V3: ◀ Auto | W3: ◀ Auto | X3: ◀ Auto | Y3: ◀ Auto | Z3: ◀ Auto | AA3: ◀ Auto | AB3: ◀ Auto
A4: Carlton, Kevin | B4: 3-3313 | C4: B2 | D4: 46114 | E4: =IF(D4="","",D4-90) -> 46024 | F4: =IF(D4="","",D4-60) -> 46054 | G4: =IF(D4="","",D4-30) -> 46084 | H4: 0 | I4: 1812 | J4: =IF(I4="","",IF(ABS(N4-W4)<=ABS(M4-W4),IF(ABS(N4-W4)<=ABS(O4-W4),"Offer 2","Offer 3"),IF(ABS(M4-W4)<=ABS(O4-W4),"Offer 1","Offer 3"))) -> Offer 1 | K4: 0 | L4: =IF(OR(I4="",K4=""),"",CEILING(I4*(1+K4),5)) -> 1815 | M4: =IF(I4="","",IF(X4="Under",CEILING(MAX(I4*1.02,MIN(V4,W4)*0.95),5),CEILING(MAX(I4*1.03,MIN(V4,W4)*0.97),5))) -> 1850 | N4: =IF(I4="","",IF(X4="Under",CEILING(MAX(I4*1.03,(V4+W4)/2*0.96),5),CEILING(MAX(I4*1.05,(V4+W4)/2*0.98),5))) -> 1870 | O4: =IF(I4="","",IF(X4="Under",CEILING(MAX(I4*1.05,MIN(V4,W4*1.01)),5),CEILING(MAX(I4*1.08,MIN(V4,W4*1.02)),5))) -> 1905 | P4: Investor Override | Q4: 46098 | T4: (904) 610-2926 | U4: 12 months / 0% increase / No concession | V4: =IF(C4="","",IFERROR(VLOOKUP(C4,SETUP!$A$9:$D$24,2,0),"⚠ Check SETUP")) -> 1595 | W4: =IF(C4="","",IFERROR(VLOOKUP(C4,SETUP!$A$9:$D$24,3,0),"⚠ Check SETUP")) -> 1806 | X4: =IF(C4="","",IFERROR(VLOOKUP(C4,SETUP!$A$9:$D$24,4,0),"⚠ Check SETUP")) -> Under | Y4: =IF(OR(I4="",M4=""),"",(M4-I4)/I4) -> 0.020971302 | Z4: =IF(OR(I4="",N4=""),"",(N4-I4)/I4) -> 0.03200883 | AA4: =IF(OR(I4="",O4=""),"",(O4-I4)/I4) -> 0.051324503 | AB4: =IF(OR(Q4="",S4<>"",P4="",I4=""),"",IF(P4="Investor Override",IF(L4="","",(L4-I4)/I4),IF(P4="Offer 1",IF(M4="","",(M4-I4)/I4),IF(P4="Offer 2",IF(N4="","",(N4-I4)/I4),IF(P4="Offer 3",IF(O4="","",(O4-I4)/I4),""))))) -> 0.0016556291
A5: Heaney, Colin | B5: 2-2309 | C5: C1 | D5: 46121 | E5: =IF(D5="","",D5-90) -> 46031 | F5: =IF(D5="","",D5-60) -> 46061 | G5: =IF(D5="","",D5-30) -> 46091 | H5: 2250 | I5: 2250 | J5: =IF(I5="","",IF(ABS(N5-W5)<=ABS(M5-W5),IF(ABS(N5-W5)<=ABS(O5-W5),"Offer 2","Offer 3"),IF(ABS(M5-W5)<=ABS(O5-W5),"Offer 1","Offer 3"))) -> Offer 3 | K5: 0.016 | L5: =IF(OR(I5="",K5=""),"",CEILING(I5*(1+K5),5)) -> 2290 | M5: =IF(I5="","",IF(X5="Under",CEILING(MAX(I5*1.02,MIN(V5,W5)*0.95),5),CEILING(MAX(I5*1.03,MIN(V5,W5)*0.97),5))) -> 2295 | N5: =IF(I5="","",IF(X5="Under",CEILING(MAX(I5*1.03,(V5+W5)/2*0.96),5),CEILING(MAX(I5*1.05,(V5+W5)/2*0.98),5))) -> 2320 | O5: =IF(I5="","",IF(X5="Under",CEILING(MAX(I5*1.05,MIN(V5,W5*1.01)),5),CEILING(MAX(I5*1.08,MIN(V5,W5*1.02)),5))) -> 2385 | P5: Investor Override | Q5: 46055 | T5: (315) 935-3708 | U5: 15 months / 2% increase / $500 concession | V5: =IF(C5="","",IFERROR(VLOOKUP(C5,SETUP!$A$9:$D$24,2,0),"⚠ Check SETUP")) -> 2406 | W5: =IF(C5="","",IFERROR(VLOOKUP(C5,SETUP!$A$9:$D$24,3,0),"⚠ Check SETUP")) -> 2361 | X5: =IF(C5="","",IFERROR(VLOOKUP(C5,SETUP!$A$9:$D$24,4,0),"⚠ Check SETUP")) -> Under | Y5: =IF(OR(I5="",M5=""),"",(M5-I5)/I5) -> 0.02 | Z5: =IF(OR(I5="",N5=""),"",(N5-I5)/I5) -> 0.031111111 | AA5: =IF(OR(I5="",O5=""),"",(O5-I5)/I5) -> 0.06 | AB5: =IF(OR(Q5="",S5<>"",P5="",I5=""),"",IF(P5="Investor Override",IF(L5="","",(L5-I5)/I5),IF(P5="Offer 1",IF(M5="","",(M5-I5)/I5),IF(P5="Offer 2",IF(N5="","",(N5-I5)/I5),IF(P5="Offer 3",IF(O5="","",(O5-I5)/I5),""))))) -> 0.017777778
A6: Taylor, Jaquez | B6: 3-3307 | C6: A5 | D6: 46125 | E6: =IF(D6="","",D6-90) -> 46035 | F6: =IF(D6="","",D6-60) -> 46065 | G6: =IF(D6="","",D6-30) -> 46095 | H6: 1427 | I6: 1427 | J6: =IF(I6="","",IF(ABS(N6-W6)<=ABS(M6-W6),IF(ABS(N6-W6)<=ABS(O6-W6),"Offer 2","Offer 3"),IF(ABS(M6-W6)<=ABS(O6-W6),"Offer 1","Offer 3"))) -> Offer 2 | K6: 0.017 | L6: =IF(OR(I6="",K6=""),"",CEILING(I6*(1+K6),5)) -> 1455 | M6: =IF(I6="","",IF(X6="Under",CEILING(MAX(I6*1.02,MIN(V6,W6)*0.95),5),CEILING(MAX(I6*1.03,MIN(V6,W6)*0.97),5))) -> 1485 | N6: =IF(I6="","",IF(X6="Under",CEILING(MAX(I6*1.03,(V6+W6)/2*0.96),5),CEILING(MAX(I6*1.05,(V6+W6)/2*0.98),5))) -> 1575 | O6: =IF(I6="","",IF(X6="Under",CEILING(MAX(I6*1.05,MIN(V6,W6*1.01)),5),CEILING(MAX(I6*1.08,MIN(V6,W6*1.02)),5))) -> 1580 | P6: Investor Override | Q6: 46070 | T6: (904) 666-0714 | U6: 12 months / 2% increase / $250 concession | V6: =IF(C6="","",IFERROR(VLOOKUP(C6,SETUP!$A$9:$D$24,2,0),"⚠ Check SETUP")) -> 1719 | W6: =IF(C6="","",IFERROR(VLOOKUP(C6,SETUP!$A$9:$D$24,3,0),"⚠ Check SETUP")) -> 1561 | X6: =IF(C6="","",IFERROR(VLOOKUP(C6,SETUP!$A$9:$D$24,4,0),"⚠ Check SETUP")) -> Under | Y6: =IF(OR(I6="",M6=""),"",(M6-I6)/I6) -> 0.040644709 | Z6: =IF(OR(I6="",N6=""),"",(N6-I6)/I6) -> 0.10371409 | AA6: =IF(OR(I6="",O6=""),"",(O6-I6)/I6) -> 0.10721794 | AB6: =IF(OR(Q6="",S6<>"",P6="",I6=""),"",IF(P6="Investor Override",IF(L6="","",(L6-I6)/I6),IF(P6="Offer 1",IF(M6="","",(M6-I6)/I6),IF(P6="Offer 2",IF(N6="","",(N6-I6)/I6),IF(P6="Offer 3",IF(O6="","",(O6-I6)/I6),""))))) -> 0.019621584
A7: Beren, Theresa | B7: 1-1403 | C7: A4 | D7: 46126 | E7: =IF(D7="","",D7-90) -> 46036 | F7: =IF(D7="","",D7-60) -> 46066 | G7: =IF(D7="","",D7-30) -> 46096 | H7: 0 | I7: 1513 | J7: =IF(I7="","",IF(ABS(N7-W7)<=ABS(M7-W7),IF(ABS(N7-W7)<=ABS(O7-W7),"Offer 2","Offer 3"),IF(ABS(M7-W7)<=ABS(O7-W7),"Offer 1","Offer 3"))) -> Offer 1 | K7: 0 | L7: =IF(OR(I7="",K7=""),"",CEILING(I7*(1+K7),5)) -> 1515 | M7: =IF(I7="","",IF(X7="Under",CEILING(MAX(I7*1.02,MIN(V7,W7)*0.95),5),CEILING(MAX(I7*1.03,MIN(V7,W7)*0.97),5))) -> 1560 | N7: =IF(I7="","",IF(X7="Under",CEILING(MAX(I7*1.03,(V7+W7)/2*0.96),5),CEILING(MAX(I7*1.05,(V7+W7)/2*0.98),5))) -> 1590 | O7: =IF(I7="","",IF(X7="Under",CEILING(MAX(I7*1.05,MIN(V7,W7*1.01)),5),CEILING(MAX(I7*1.08,MIN(V7,W7*1.02)),5))) -> 1635 | P7: Investor Override | Q7: 46051 | T7: (321) 514-5112 | U7: 12 months / 0% increase / $500 concession | V7: =IF(C7="","",IFERROR(VLOOKUP(C7,SETUP!$A$9:$D$24,2,0),"⚠ Check SETUP")) -> 1421 | W7: =IF(C7="","",IFERROR(VLOOKUP(C7,SETUP!$A$9:$D$24,3,0),"⚠ Check SETUP")) -> 1424 | X7: =IF(C7="","",IFERROR(VLOOKUP(C7,SETUP!$A$9:$D$24,4,0),"⚠ Check SETUP")) -> Over | Y7: =IF(OR(I7="",M7=""),"",(M7-I7)/I7) -> 0.031064111 | Z7: =IF(OR(I7="",N7=""),"",(N7-I7)/I7) -> 0.050892267 | AA7: =IF(OR(I7="",O7=""),"",(O7-I7)/I7) -> 0.080634501 | AB7: =IF(OR(Q7="",S7<>"",P7="",I7=""),"",IF(P7="Investor Override",IF(L7="","",(L7-I7)/I7),IF(P7="Offer 1",IF(M7="","",(M7-I7)/I7),IF(P7="Offer 2",IF(N7="","",(N7-I7)/I7),IF(P7="Offer 3",IF(O7="","",(O7-I7)/I7),""))))) -> 0.0013218771
A8: Lee, Aspen | B8: 3-3115 | C8: A1 | D8: 46126 | E8: =IF(D8="","",D8-90) -> 46036 | F8: =IF(D8="","",D8-60) -> 46066 | G8: =IF(D8="","",D8-30) -> 46096 | H8: 0 | I8: 1498 | J8: =IF(I8="","",IF(ABS(N8-W8)<=ABS(M8-W8),IF(ABS(N8-W8)<=ABS(O8-W8),"Offer 2","Offer 3"),IF(ABS(M8-W8)<=ABS(O8-W8),"Offer 1","Offer 3"))) -> Offer 1 | K8: 0.012 | L8: =IF(OR(I8="",K8=""),"",CEILING(I8*(1+K8),5)) -> 1520 | M8: =IF(I8="","",IF(X8="Under",CEILING(MAX(I8*1.02,MIN(V8,W8)*0.95),5),CEILING(MAX(I8*1.03,MIN(V8,W8)*0.97),5))) -> 1530 | N8: =IF(I8="","",IF(X8="Under",CEILING(MAX(I8*1.03,(V8+W8)/2*0.96),5),CEILING(MAX(I8*1.05,(V8+W8)/2*0.98),5))) -> 1545 | O8: =IF(I8="","",IF(X8="Under",CEILING(MAX(I8*1.05,MIN(V8,W8*1.01)),5),CEILING(MAX(I8*1.08,MIN(V8,W8*1.02)),5))) -> 1575 | S8: 46058 | T8: (904) 837-6446 | U8: Relocating | V8: =IF(C8="","",IFERROR(VLOOKUP(C8,SETUP!$A$9:$D$24,2,0),"⚠ Check SETUP")) -> 1595 | W8: =IF(C8="","",IFERROR(VLOOKUP(C8,SETUP!$A$9:$D$24,3,0),"⚠ Check SETUP")) -> 1504 | X8: =IF(C8="","",IFERROR(VLOOKUP(C8,SETUP!$A$9:$D$24,4,0),"⚠ Check SETUP")) -> Under | Y8: =IF(OR(I8="",M8=""),"",(M8-I8)/I8) -> 0.021361816 | Z8: =IF(OR(I8="",N8=""),"",(N8-I8)/I8) -> 0.031375167 | AA8: =IF(OR(I8="",O8=""),"",(O8-I8)/I8) -> 0.051401869 | AB8: =IF(OR(Q8="",S8<>"",P8="",I8=""),"",IF(P8="Investor Override",IF(L8="","",(L8-I8)/I8),IF(P8="Offer 1",IF(M8="","",(M8-I8)/I8),IF(P8="Offer 2",IF(N8="","",(N8-I8)/I8),IF(P8="Offer 3",IF(O8="","",(O8-I8)/I8),"")))))
A9: Anderson, Lilah | B9: 1-1113 | C9: A3 | D9: 46126 | E9: =IF(D9="","",D9-90) -> 46036 | F9: =IF(D9="","",D9-60) -> 46066 | G9: =IF(D9="","",D9-30) -> 46096 | H9: 0 | I9: 1822 | J9: =IF(I9="","",IF(ABS(N9-W9)<=ABS(M9-W9),IF(ABS(N9-W9)<=ABS(O9-W9),"Offer 2","Offer 3"),IF(ABS(M9-W9)<=ABS(O9-W9),"Offer 1","Offer 3"))) -> Offer 1 | K9: 0 | L9: =IF(OR(I9="",K9=""),"",CEILING(I9*(1+K9),5)) -> 1825 | M9: =IF(I9="","",IF(X9="Under",CEILING(MAX(I9*1.02,MIN(V9,W9)*0.95),5),CEILING(MAX(I9*1.03,MIN(V9,W9)*0.97),5))) -> 1860 | N9: =IF(I9="","",IF(X9="Under",CEILING(MAX(I9*1.03,(V9+W9)/2*0.96),5),CEILING(MAX(I9*1.05,(V9+W9)/2*0.98),5))) -> 1880 | O9: =IF(I9="","",IF(X9="Under",CEILING(MAX(I9*1.05,MIN(V9,W9*1.01)),5),CEILING(MAX(I9*1.08,MIN(V9,W9*1.02)),5))) -> 1915 | S9: 46071 | T9: (708) 557-3795 | U9: Relocating to Japan where spouse is stationed | V9: =IF(C9="","",IFERROR(VLOOKUP(C9,SETUP!$A$9:$D$24,2,0),"⚠ Check SETUP")) -> 1878 | W9: =IF(C9="","",IFERROR(VLOOKUP(C9,SETUP!$A$9:$D$24,3,0),"⚠ Check SETUP")) -> 1727 | X9: =IF(C9="","",IFERROR(VLOOKUP(C9,SETUP!$A$9:$D$24,4,0),"⚠ Check SETUP")) -> Under | Y9: =IF(OR(I9="",M9=""),"",(M9-I9)/I9) -> 0.020856202 | Z9: =IF(OR(I9="",N9=""),"",(N9-I9)/I9) -> 0.03183315 | AA9: =IF(OR(I9="",O9=""),"",(O9-I9)/I9) -> 0.05104281 | AB9: =IF(OR(Q9="",S9<>"",P9="",I9=""),"",IF(P9="Investor Override",IF(L9="","",(L9-I9)/I9),IF(P9="Offer 1",IF(M9="","",(M9-I9)/I9),IF(P9="Offer 2",IF(N9="","",(N9-I9)/I9),IF(P9="Offer 3",IF(O9="","",(O9-I9)/I9),"")))))
A10: St Louis, Sarah | B10: 3-3320 | C10: B3 | D10: 46128 | E10: =IF(D10="","",D10-90) -> 46038 | F10: =IF(D10="","",D10-60) -> 46068 | G10: =IF(D10="","",D10-30) -> 46098 | H10: 0 | I10: 1836 | J10: =IF(I10="","",IF(ABS(N10-W10)<=ABS(M10-W10),IF(ABS(N10-W10)<=ABS(O10-W10),"Offer 2","Offer 3"),IF(ABS(M10-W10)<=ABS(O10-W10),"Offer 1","Offer 3"))) -> Offer 3 | K10: 0.002 | L10: =IF(OR(I10="",K10=""),"",CEILING(I10*(1+K10),5)) -> 1840 | M10: =IF(I10="","",IF(X10="Under",CEILING(MAX(I10*1.02,MIN(V10,W10)*0.95),5),CEILING(MAX(I10*1.03,MIN(V10,W10)*0.97),5))) -> 1875 | N10: =IF(I10="","",IF(X10="Under",CEILING(MAX(I10*1.03,(V10+W10)/2*0.96),5),CEILING(MAX(I10*1.05,(V10+W10)/2*0.98),5))) -> 1895 | O10: =IF(I10="","",IF(X10="Under",CEILING(MAX(I10*1.05,MIN(V10,W10*1.01)),5),CEILING(MAX(I10*1.08,MIN(V10,W10*1.02)),5))) -> 1930 | P10: Investor Override | Q10: 46101 | T10: (904) 662-2943 | U10: 15 months / 1% increase / No concession | V10: =IF(C10="","",IFERROR(VLOOKUP(C10,SETUP!$A$9:$D$24,2,0),"⚠ Check SETUP")) -> 1880 | W10: =IF(C10="","",IFERROR(VLOOKUP(C10,SETUP!$A$9:$D$24,3,0),"⚠ Check SETUP")) -> 1976 | X10: =IF(C10="","",IFERROR(VLOOKUP(C10,SETUP!$A$9:$D$24,4,0),"⚠ Check SETUP")) -> Under | Y10: =IF(OR(I10="",M10=""),"",(M10-I10)/I10) -> 0.02124183 | Z10: =IF(OR(I10="",N10=""),"",(N10-I10)/I10) -> 0.032135076 | AA10: =IF(OR(I10="",O10=""),"",(O10-I10)/I10) -> 0.051198257 | AB10: =IF(OR(Q10="",S10<>"",P10="",I10=""),"",IF(P10="Investor Override",IF(L10="","",(L10-I10)/I10),IF(P10="Offer 1",IF(M10="","",(M10-I10)/I10),IF(P10="Offer 2",IF(N10="","",(N10-I10)/I10),IF(P10="Offer 3",IF(O10="","",(O10-I10)/I10),""))))) -> 0.0021786492
A11: Johnson, Toby | B11: 2-2411 | C11: B1 | D11: 46128 | E11: =IF(D11="","",D11-90) -> 46038 | F11: =IF(D11="","",D11-60) -> 46068 | G11: =IF(D11="","",D11-30) -> 46098 | H11: 1843 | I11: 1843 | J11: =IF(I11="","",IF(ABS(N11-W11)<=ABS(M11-W11),IF(ABS(N11-W11)<=ABS(O11-W11),"Offer 2","Offer 3"),IF(ABS(M11-W11)<=ABS(O11-W11),"Offer 1","Offer 3"))) -> Offer 1 | K11: 0 | L11: =IF(OR(I11="",K11=""),"",CEILING(I11*(1+K11),5)) -> 1845 | M11: =IF(I11="","",IF(X11="Under",CEILING(MAX(I11*1.02,MIN(V11,W11)*0.95),5),CEILING(MAX(I11*1.03,MIN(V11,W11)*0.97),5))) -> 1880 | N11: =IF(I11="","",IF(X11="Under",CEILING(MAX(I11*1.03,(V11+W11)/2*0.96),5),CEILING(MAX(I11*1.05,(V11+W11)/2*0.98),5))) -> 1900 | O11: =IF(I11="","",IF(X11="Under",CEILING(MAX(I11*1.05,MIN(V11,W11*1.01)),5),CEILING(MAX(I11*1.08,MIN(V11,W11*1.02)),5))) -> 1940 | P11: Investor Override | Q11: 46071 | T11: (954) 793-7114 | U11: 15 months / 0% increase / $500 concession | V11: =IF(C11="","",IFERROR(VLOOKUP(C11,SETUP!$A$9:$D$24,2,0),"⚠ Check SETUP")) -> 1809 | W11: =IF(C11="","",IFERROR(VLOOKUP(C11,SETUP!$A$9:$D$24,3,0),"⚠ Check SETUP")) -> 1764 | X11: =IF(C11="","",IFERROR(VLOOKUP(C11,SETUP!$A$9:$D$24,4,0),"⚠ Check SETUP")) -> Under | Y11: =IF(OR(I11="",M11=""),"",(M11-I11)/I11) -> 0.020075963 | Z11: =IF(OR(I11="",N11=""),"",(N11-I11)/I11) -> 0.030927835 | AA11: =IF(OR(I11="",O11=""),"",(O11-I11)/I11) -> 0.052631579 | AB11: =IF(OR(Q11="",S11<>"",P11="",I11=""),"",IF(P11="Investor Override",IF(L11="","",(L11-I11)/I11),IF(P11="Offer 1",IF(M11="","",(M11-I11)/I11),IF(P11="Offer 2",IF(N11="","",(N11-I11)/I11),IF(P11="Offer 3",IF(O11="","",(O11-I11)/I11),""))))) -> 0.0010851872
A12: Johnson, Alysa | B12: 1-1336 | C12: B1 | D12: 46132 | E12: =IF(D12="","",D12-90) -> 46042 | F12: =IF(D12="","",D12-60) -> 46072 | G12: =IF(D12="","",D12-30) -> 46102 | H12: 1803 | I12: 1803 | J12: =IF(I12="","",IF(ABS(N12-W12)<=ABS(M12-W12),IF(ABS(N12-W12)<=ABS(O12-W12),"Offer 2","Offer 3"),IF(ABS(M12-W12)<=ABS(O12-W12),"Offer 1","Offer 3"))) -> Offer 1 | K12: 0 | L12: =IF(OR(I12="",K12=""),"",CEILING(I12*(1+K12),5)) -> 1805 | M12: =IF(I12="","",IF(X12="Under",CEILING(MAX(I12*1.02,MIN(V12,W12)*0.95),5),CEILING(MAX(I12*1.03,MIN(V12,W12)*0.97),5))) -> 1840 | N12: =IF(I12="","",IF(X12="Under",CEILING(MAX(I12*1.03,(V12+W12)/2*0.96),5),CEILING(MAX(I12*1.05,(V12+W12)/2*0.98),5))) -> 1860 | O12: =IF(I12="","",IF(X12="Under",CEILING(MAX(I12*1.05,MIN(V12,W12*1.01)),5),CEILING(MAX(I12*1.08,MIN(V12,W12*1.02)),5))) -> 1895 | R12: 46077 | T12: (904) 753-8047 | U12: Larger apartment | V12: =IF(C12="","",IFERROR(VLOOKUP(C12,SETUP!$A$9:$D$24,2,0),"⚠ Check SETUP")) -> 1809 | W12: =IF(C12="","",IFERROR(VLOOKUP(C12,SETUP!$A$9:$D$24,3,0),"⚠ Check SETUP")) -> 1764 | X12: =IF(C12="","",IFERROR(VLOOKUP(C12,SETUP!$A$9:$D$24,4,0),"⚠ Check SETUP")) -> Under | Y12: =IF(OR(I12="",M12=""),"",(M12-I12)/I12) -> 0.020521353 | Z12: =IF(OR(I12="",N12=""),"",(N12-I12)/I12) -> 0.031613977 | AA12: =IF(OR(I12="",O12=""),"",(O12-I12)/I12) -> 0.051026068 | AB12: =IF(OR(Q12="",S12<>"",P12="",I12=""),"",IF(P12="Investor Override",IF(L12="","",(L12-I12)/I12),IF(P12="Offer 1",IF(M12="","",(M12-I12)/I12),IF(P12="Offer 2",IF(N12="","",(N12-I12)/I12),IF(P12="Offer 3",IF(O12="","",(O12-I12)/I12),"")))))
A13: Tumu, Saranya | B13: 1-1327 | C13: A4 | D13: 46133 | E13: =IF(D13="","",D13-90) -> 46043 | F13: =IF(D13="","",D13-60) -> 46073 | G13: =IF(D13="","",D13-30) -> 46103 | H13: 1439 | I13: 1439 | J13: =IF(I13="","",IF(ABS(N13-W13)<=ABS(M13-W13),IF(ABS(N13-W13)<=ABS(O13-W13),"Offer 2","Offer 3"),IF(ABS(M13-W13)<=ABS(O13-W13),"Offer 1","Offer 3"))) -> Offer 1 | K13: 0 | L13: =IF(OR(I13="",K13=""),"",CEILING(I13*(1+K13),5)) -> 1440 | M13: =IF(I13="","",IF(X13="Under",CEILING(MAX(I13*1.02,MIN(V13,W13)*0.95),5),CEILING(MAX(I13*1.03,MIN(V13,W13)*0.97),5))) -> 1485 | N13: =IF(I13="","",IF(X13="Under",CEILING(MAX(I13*1.03,(V13+W13)/2*0.96),5),CEILING(MAX(I13*1.05,(V13+W13)/2*0.98),5))) -> 1515 | O13: =IF(I13="","",IF(X13="Under",CEILING(MAX(I13*1.05,MIN(V13,W13*1.01)),5),CEILING(MAX(I13*1.08,MIN(V13,W13*1.02)),5))) -> 1555 | P13: Investor Override | Q13: 46073 | T13: (732) 487-0507 | U13: 12 months / 0% increase / $750 concession | V13: =IF(C13="","",IFERROR(VLOOKUP(C13,SETUP!$A$9:$D$24,2,0),"⚠ Check SETUP")) -> 1421 | W13: =IF(C13="","",IFERROR(VLOOKUP(C13,SETUP!$A$9:$D$24,3,0),"⚠ Check SETUP")) -> 1424 | X13: =IF(C13="","",IFERROR(VLOOKUP(C13,SETUP!$A$9:$D$24,4,0),"⚠ Check SETUP")) -> Over | Y13: =IF(OR(I13="",M13=""),"",(M13-I13)/I13) -> 0.031966644 | Z13: =IF(OR(I13="",N13=""),"",(N13-I13)/I13) -> 0.052814454 | AA13: =IF(OR(I13="",O13=""),"",(O13-I13)/I13) -> 0.080611536 | AB13: =IF(OR(Q13="",S13<>"",P13="",I13=""),"",IF(P13="Investor Override",IF(L13="","",(L13-I13)/I13),IF(P13="Offer 1",IF(M13="","",(M13-I13)/I13),IF(P13="Offer 2",IF(N13="","",(N13-I13)/I13),IF(P13="Offer 3",IF(O13="","",(O13-I13)/I13),""))))) -> 0.00069492703
A14: Lin, Jason | B14: 1-1303 | C14: A4 | D14: 46135 | E14: =IF(D14="","",D14-90) -> 46045 | F14: =IF(D14="","",D14-60) -> 46075 | G14: =IF(D14="","",D14-30) -> 46105 | H14: 0 | I14: 1444 | J14: =IF(I14="","",IF(ABS(N14-W14)<=ABS(M14-W14),IF(ABS(N14-W14)<=ABS(O14-W14),"Offer 2","Offer 3"),IF(ABS(M14-W14)<=ABS(O14-W14),"Offer 1","Offer 3"))) -> Offer 1 | K14: 0 | L14: 1444 | M14: =IF(I14="","",IF(X14="Under",CEILING(MAX(I14*1.02,MIN(V14,W14)*0.95),5),CEILING(MAX(I14*1.03,MIN(V14,W14)*0.97),5))) -> 1490 | N14: =IF(I14="","",IF(X14="Under",CEILING(MAX(I14*1.03,(V14+W14)/2*0.96),5),CEILING(MAX(I14*1.05,(V14+W14)/2*0.98),5))) -> 1520 | O14: =IF(I14="","",IF(X14="Under",CEILING(MAX(I14*1.05,MIN(V14,W14*1.01)),5),CEILING(MAX(I14*1.08,MIN(V14,W14*1.02)),5))) -> 1560 | P14: Investor Override | Q14: 46125 | T14: (917) 518-3881 | U14: 12 months / 0% increase / Two months free | V14: =IF(C14="","",IFERROR(VLOOKUP(C14,SETUP!$A$9:$D$24,2,0),"⚠ Check SETUP")) -> 1421 | W14: =IF(C14="","",IFERROR(VLOOKUP(C14,SETUP!$A$9:$D$24,3,0),"⚠ Check SETUP")) -> 1424 | X14: =IF(C14="","",IFERROR(VLOOKUP(C14,SETUP!$A$9:$D$24,4,0),"⚠ Check SETUP")) -> Over | Y14: =IF(OR(I14="",M14=""),"",(M14-I14)/I14) -> 0.031855956 | Z14: =IF(OR(I14="",N14=""),"",(N14-I14)/I14) -> 0.052631579 | AA14: =IF(OR(I14="",O14=""),"",(O14-I14)/I14) -> 0.08033241 | AB14: =IF(OR(Q14="",S14<>"",P14="",I14=""),"",IF(P14="Investor Override",IF(L14="","",(L14-I14)/I14),IF(P14="Offer 1",IF(M14="","",(M14-I14)/I14),IF(P14="Offer 2",IF(N14="","",(N14-I14)/I14),IF(P14="Offer 3",IF(O14="","",(O14-I14)/I14),""))))) -> 0
A15: Naylor, Kyleigh | B15: 1-1209 | C15: S2 | D15: 46137 | E15: =IF(D15="","",D15-90) -> 46047 | F15: =IF(D15="","",D15-60) -> 46077 | G15: =IF(D15="","",D15-30) -> 46107 | H15: 500 | I15: 1329 | J15: =IF(I15="","",IF(ABS(N15-W15)<=ABS(M15-W15),IF(ABS(N15-W15)<=ABS(O15-W15),"Offer 2","Offer 3"),IF(ABS(M15-W15)<=ABS(O15-W15),"Offer 1","Offer 3"))) -> Offer 1 | K15: 0 | L15: =IF(OR(I15="",K15=""),"",CEILING(I15*(1+K15),5)) -> 1330 | M15: =IF(I15="","",IF(X15="Under",CEILING(MAX(I15*1.02,MIN(V15,W15)*0.95),5),CEILING(MAX(I15*1.03,MIN(V15,W15)*0.97),5))) -> 1370 | N15: =IF(I15="","",IF(X15="Under",CEILING(MAX(I15*1.03,(V15+W15)/2*0.96),5),CEILING(MAX(I15*1.05,(V15+W15)/2*0.98),5))) -> 1400 | O15: =IF(I15="","",IF(X15="Under",CEILING(MAX(I15*1.05,MIN(V15,W15*1.01)),5),CEILING(MAX(I15*1.08,MIN(V15,W15*1.02)),5))) -> 1440 | P15: Investor Override | Q15: 46071 | T15: (804) 847-8476 | U15: 12 months / 0% increase / $250 concession | V15: =IF(C15="","",IFERROR(VLOOKUP(C15,SETUP!$A$9:$D$24,2,0),"⚠ Check SETUP")) -> 1301 | W15: =IF(C15="","",IFERROR(VLOOKUP(C15,SETUP!$A$9:$D$24,3,0),"⚠ Check SETUP")) -> 1298 | X15: =IF(C15="","",IFERROR(VLOOKUP(C15,SETUP!$A$9:$D$24,4,0),"⚠ Check SETUP")) -> Over | Y15: =IF(OR(I15="",M15=""),"",(M15-I15)/I15) -> 0.030850263 | Z15: =IF(OR(I15="",N15=""),"",(N15-I15)/I15) -> 0.053423627 | AA15: =IF(OR(I15="",O15=""),"",(O15-I15)/I15) -> 0.083521445 | AB15: =IF(OR(Q15="",S15<>"",P15="",I15=""),"",IF(P15="Investor Override",IF(L15="","",(L15-I15)/I15),IF(P15="Offer 1",IF(M15="","",(M15-I15)/I15),IF(P15="Offer 2",IF(N15="","",(N15-I15)/I15),IF(P15="Offer 3",IF(O15="","",(O15-I15)/I15),""))))) -> 0.00075244545
A16: Gallagher, Brittany | B16: 1-1331 | C16: B8 | D16: 46139 | E16: =IF(D16="","",D16-90) -> 46049 | F16: =IF(D16="","",D16-60) -> 46079 | G16: =IF(D16="","",D16-30) -> 46109 | H16: 0 | I16: 2216 | J16: =IF(I16="","",IF(ABS(N16-W16)<=ABS(M16-W16),IF(ABS(N16-W16)<=ABS(O16-W16),"Offer 2","Offer 3"),IF(ABS(M16-W16)<=ABS(O16-W16),"Offer 1","Offer 3"))) -> Offer 1 | K16: 0 | L16: =IF(OR(I16="",K16=""),"",CEILING(I16*(1+K16),5)) -> 2220 | M16: =IF(I16="","",IF(X16="Under",CEILING(MAX(I16*1.02,MIN(V16,W16)*0.95),5),CEILING(MAX(I16*1.03,MIN(V16,W16)*0.97),5))) -> 2285 | N16: =IF(I16="","",IF(X16="Under",CEILING(MAX(I16*1.03,(V16+W16)/2*0.96),5),CEILING(MAX(I16*1.05,(V16+W16)/2*0.98),5))) -> 2330 | O16: =IF(I16="","",IF(X16="Under",CEILING(MAX(I16*1.05,MIN(V16,W16*1.01)),5),CEILING(MAX(I16*1.08,MIN(V16,W16*1.02)),5))) -> 2395 | P16: Investor Override | Q16: 46071 | T16: (410) 935-6764 | U16: 15 months / 0% increase / $500 concession | V16: =IF(C16="","",IFERROR(VLOOKUP(C16,SETUP!$A$9:$D$24,2,0),"⚠ Check SETUP")) -> 1969 | W16: =IF(C16="","",IFERROR(VLOOKUP(C16,SETUP!$A$9:$D$24,3,0),"⚠ Check SETUP")) -> 1617 | X16: =IF(C16="","",IFERROR(VLOOKUP(C16,SETUP!$A$9:$D$24,4,0),"⚠ Check SETUP")) -> Over | Y16: =IF(OR(I16="",M16=""),"",(M16-I16)/I16) -> 0.031137184 | Z16: =IF(OR(I16="",N16=""),"",(N16-I16)/I16) -> 0.051444043 | AA16: =IF(OR(I16="",O16=""),"",(O16-I16)/I16) -> 0.080776173 | AB16: =IF(OR(Q16="",S16<>"",P16="",I16=""),"",IF(P16="Investor Override",IF(L16="","",(L16-I16)/I16),IF(P16="Offer 1",IF(M16="","",(M16-I16)/I16),IF(P16="Offer 2",IF(N16="","",(N16-I16)/I16),IF(P16="Offer 3",IF(O16="","",(O16-I16)/I16),""))))) -> 0.0018050542
A17: Gonzalez, Roger | B17: 3-3211 | C17: A1 | D17: 46140 | E17: =IF(D17="","",D17-90) -> 46050 | F17: =IF(D17="","",D17-60) -> 46080 | G17: =IF(D17="","",D17-30) -> 46110 | H17: 0 | I17: 1469 | J17: =IF(I17="","",IF(ABS(N17-W17)<=ABS(M17-W17),IF(ABS(N17-W17)<=ABS(O17-W17),"Offer 2","Offer 3"),IF(ABS(M17-W17)<=ABS(O17-W17),"Offer 1","Offer 3"))) -> Offer 1 | K17: 0 | L17: =IF(OR(I17="",K17=""),"",CEILING(I17*(1+K17),5)) -> 1470 | M17: =IF(I17="","",IF(X17="Under",CEILING(MAX(I17*1.02,MIN(V17,W17)*0.95),5),CEILING(MAX(I17*1.03,MIN(V17,W17)*0.97),5))) -> 1500 | N17: =IF(I17="","",IF(X17="Under",CEILING(MAX(I17*1.03,(V17+W17)/2*0.96),5),CEILING(MAX(I17*1.05,(V17+W17)/2*0.98),5))) -> 1515 | O17: =IF(I17="","",IF(X17="Under",CEILING(MAX(I17*1.05,MIN(V17,W17*1.01)),5),CEILING(MAX(I17*1.08,MIN(V17,W17*1.02)),5))) -> 1545 | S17: 46076 | T17: (904) 831-7598 | U17: Price/special - two months free elsewhere | V17: =IF(C17="","",IFERROR(VLOOKUP(C17,SETUP!$A$9:$D$24,2,0),"⚠ Check SETUP")) -> 1595 | W17: =IF(C17="","",IFERROR(VLOOKUP(C17,SETUP!$A$9:$D$24,3,0),"⚠ Check SETUP")) -> 1504 | X17: =IF(C17="","",IFERROR(VLOOKUP(C17,SETUP!$A$9:$D$24,4,0),"⚠ Check SETUP")) -> Under | Y17: =IF(OR(I17="",M17=""),"",(M17-I17)/I17) -> 0.021102791 | Z17: =IF(OR(I17="",N17=""),"",(N17-I17)/I17) -> 0.031313819 | AA17: =IF(OR(I17="",O17=""),"",(O17-I17)/I17) -> 0.051735875 | AB17: =IF(OR(Q17="",S17<>"",P17="",I17=""),"",IF(P17="Investor Override",IF(L17="","",(L17-I17)/I17),IF(P17="Offer 1",IF(M17="","",(M17-I17)/I17),IF(P17="Offer 2",IF(N17="","",(N17-I17)/I17),IF(P17="Offer 3",IF(O17="","",(O17-I17)/I17),"")))))
A18: Wade, DeVonte | B18: 1-1109 | C18: S2 | D18: 46140 | E18: =IF(D18="","",D18-90) -> 46050 | F18: =IF(D18="","",D18-60) -> 46080 | G18: =IF(D18="","",D18-30) -> 46110 | H18: 500 | I18: 1337 | J18: =IF(I18="","",IF(ABS(N18-W18)<=ABS(M18-W18),IF(ABS(N18-W18)<=ABS(O18-W18),"Offer 2","Offer 3"),IF(ABS(M18-W18)<=ABS(O18-W18),"Offer 1","Offer 3"))) -> Offer 1 | K18: 0 | L18: =IF(OR(I18="",K18=""),"",CEILING(I18*(1+K18),5)) -> 1340 | M18: =IF(I18="","",IF(X18="Under",CEILING(MAX(I18*1.02,MIN(V18,W18)*0.95),5),CEILING(MAX(I18*1.03,MIN(V18,W18)*0.97),5))) -> 1380 | N18: =IF(I18="","",IF(X18="Under",CEILING(MAX(I18*1.03,(V18+W18)/2*0.96),5),CEILING(MAX(I18*1.05,(V18+W18)/2*0.98),5))) -> 1405 | O18: =IF(I18="","",IF(X18="Under",CEILING(MAX(I18*1.05,MIN(V18,W18*1.01)),5),CEILING(MAX(I18*1.08,MIN(V18,W18*1.02)),5))) -> 1445 | S18: 46055 | T18: (941) 264-3162 | U18: Unhappy with site management | V18: =IF(C18="","",IFERROR(VLOOKUP(C18,SETUP!$A$9:$D$24,2,0),"⚠ Check SETUP")) -> 1301 | W18: =IF(C18="","",IFERROR(VLOOKUP(C18,SETUP!$A$9:$D$24,3,0),"⚠ Check SETUP")) -> 1298 | X18: =IF(C18="","",IFERROR(VLOOKUP(C18,SETUP!$A$9:$D$24,4,0),"⚠ Check SETUP")) -> Over | Y18: =IF(OR(I18="",M18=""),"",(M18-I18)/I18) -> 0.032161556 | Z18: =IF(OR(I18="",N18=""),"",(N18-I18)/I18) -> 0.050860135 | AA18: =IF(OR(I18="",O18=""),"",(O18-I18)/I18) -> 0.080777861 | AB18: =IF(OR(Q18="",S18<>"",P18="",I18=""),"",IF(P18="Investor Override",IF(L18="","",(L18-I18)/I18),IF(P18="Offer 1",IF(M18="","",(M18-I18)/I18),IF(P18="Offer 2",IF(N18="","",(N18-I18)/I18),IF(P18="Offer 3",IF(O18="","",(O18-I18)/I18),"")))))
A19: Ricks, Tamara | B19: 1-1239 | C19: B3 | D19: 46142 | E19: =IF(D19="","",D19-90) -> 46052 | F19: =IF(D19="","",D19-60) -> 46082 | G19: =IF(D19="","",D19-30) -> 46112 | H19: 1906 | I19: 1906 | J19: =IF(I19="","",IF(ABS(N19-W19)<=ABS(M19-W19),IF(ABS(N19-W19)<=ABS(O19-W19),"Offer 2","Offer 3"),IF(ABS(M19-W19)<=ABS(O19-W19),"Offer 1","Offer 3"))) -> Offer 2 | K19: 0 | L19: =IF(OR(I19="",K19=""),"",CEILING(I19*(1+K19),5)) -> 1910 | M19: =IF(I19="","",IF(X19="Under",CEILING(MAX(I19*1.02,MIN(V19,W19)*0.95),5),CEILING(MAX(I19*1.03,MIN(V19,W19)*0.97),5))) -> 1945 | N19: =IF(I19="","",IF(X19="Under",CEILING(MAX(I19*1.03,(V19+W19)/2*0.96),5),CEILING(MAX(I19*1.05,(V19+W19)/2*0.98),5))) -> 1965 | O19: =IF(I19="","",IF(X19="Under",CEILING(MAX(I19*1.05,MIN(V19,W19*1.01)),5),CEILING(MAX(I19*1.08,MIN(V19,W19*1.02)),5))) -> 2005 | S19: 46066 | T19: (904) 694-8194 | U19: Relocating to be with family in Virginia (unhappy with upstairs neighbor) | V19: =IF(C19="","",IFERROR(VLOOKUP(C19,SETUP!$A$9:$D$24,2,0),"⚠ Check SETUP")) -> 1880 | W19: =IF(C19="","",IFERROR(VLOOKUP(C19,SETUP!$A$9:$D$24,3,0),"⚠ Check SETUP")) -> 1976 | X19: =IF(C19="","",IFERROR(VLOOKUP(C19,SETUP!$A$9:$D$24,4,0),"⚠ Check SETUP")) -> Under | Y19: =IF(OR(I19="",M19=""),"",(M19-I19)/I19) -> 0.0204617 | Z19: =IF(OR(I19="",N19=""),"",(N19-I19)/I19) -> 0.030954879 | AA19: =IF(OR(I19="",O19=""),"",(O19-I19)/I19) -> 0.051941238 | AB19: =IF(OR(Q19="",S19<>"",P19="",I19=""),"",IF(P19="Investor Override",IF(L19="","",(L19-I19)/I19),IF(P19="Offer 1",IF(M19="","",(M19-I19)/I19),IF(P19="Offer 2",IF(N19="","",(N19-I19)/I19),IF(P19="Offer 3",IF(O19="","",(O19-I19)/I19),"")))))
A21: RETENTION ANALYSIS
A22: Metric | B22: Count | C22: % of Expirations | D22: % of Decided | E22: Status
A23: Total Lease Expirations | B23: =COUNTA(A4:A19) -> 16
A24: Renewals Signed | B24: =COUNTA(Q4:Q19) -> 10 | C24: =IFERROR(B24/B23,"-") -> 0.625 | D24: =IFERROR(B24/(B24+B25),"-") -> 0.66666667 | E24: =IF(B23=0,"Awaiting data",IF(B24/B23>=0.6,"On Track ✓","Needs Attention ⚠")) -> On Track ✓
A25: NTV's Received | B25: =COUNTA(S4:S19) -> 5 | C25: =IFERROR(B25/B23,"-") -> 0.3125 | D25: =IFERROR(B25/(B24+B25),"-") -> 0.33333333 | E25: =IF(B23=0,"Awaiting data",IF(B25/B23<=0.2,"Acceptable","High NTV ⚠")) -> High NTV ⚠
A26: Transfers | B26: =COUNTA(R4:R19) -> 1 | C26: =IFERROR(B26/B23,"-") -> 0.0625 | D26: — | E26: Resident retained in portfolio
A27: Pending / Not Yet Decided | B27: =MAX(0,B23-B24-B25-B26) -> 0 | C27: =IFERROR(B27/B23,"-") -> 0 | D27: — | E27: =IF(B27=0,"All accounted for ✓","Follow up needed") -> All accounted for ✓
A29: RETENTION RATE (Renewals ÷ Total Expirations) | C29: =IFERROR(B24/B23,"-") -> 0.625 | D29: =IF(B23=0,"Enter resident data to calculate",IF(B24/B23>=0.6,"✓ Meeting target retention","⚠ Below target — review offers")) -> ✓ Meeting target retention
A30: RETENTION RATE (Renewals ÷ Renewals + NTVs) ← of decided residents | C30: =IFERROR(B24/(B24+B25),"-") -> 0.66666667 | D30: Excludes pending residents — only counts those who have made a decision (renewed or NTV'd)
A33: Legend
A34: Renewed (auto: enter date in Renewal Signed)
A35: Pending Signature (manual: apply yellow fill)
A36: NTV / Notice to Vacate (auto: enter date in NTV Rcv'd)
A37: Transfer (auto: enter date in Transfer)
A38: MTM / Month-to-Month (manual: apply gray fill)

Sheet May 2026
A1: =SETUP!B3&" - "&SETUP!B4&" Renewals" -> RISE Bartram Park - April 2026 Renewals
A2: Name | B2: Unit | C2: Unit Type | D2: Expiration Date | E2: 90-Day Notice | F2: 60-Day Notice | G2: 30-Day Notice | H2: Deposit Held | I2: Current Rate | J2: Recommended Offer | K2: Investor Override % Increase | L2: Investor Override Offer | M2: Offer 1 Conservative | N2: Offer 2 Balanced | O2: Offer 3 Aggressive | P2: Signed Offer | Q2: Renewal Signed | R2: Transfer | S2: NTV Rcv'd | T2: Phone | U2: Notes | V2: Market Rate | W2: Budget | X2: Occupancy (Under/Over) | Y2: Rent Growth Offer 1 | Z2: Rent Growth Offer 2 | AA2: Rent Growth Offer 3 | AB2: Signed Rent Growth
A3: ▼ Enter | B3: ▼ Enter | C3: ▼ Enter | D3: ▼ Enter | E3: ◀ Auto | F3: ◀ Auto | G3: ◀ Auto | H3: ▼ Enter | I3: ▼ Enter | J3: ◀ Auto | K3: ▼ Enter | L3: ◀ Auto | M3: ◀ Auto | N3: ◀ Auto | O3: ◀ Auto | P3: ▼ Select | Q3: ▼ Enter | R3: ▼ Enter | S3: ▼ Enter | T3: ▼ Enter | U3: ▼ Enter | V3: ◀ Auto | W3: ◀ Auto | X3: ◀ Auto | Y3: ◀ Auto | Z3: ◀ Auto | AA3: ◀ Auto | AB3: ◀ Auto
A4: Farraye, Andrew | B4: 1-1411 | C4: B8 | D4: 46145 | E4: =IF(D4="","",D4-90) -> 46055 | F4: =IF(D4="","",D4-60) -> 46085 | G4: =IF(D4="","",D4-30) -> 46115 | H4: 0 | I4: 1937 | J4: =IF(I4="","",IF(ABS(N4-W4)<=ABS(M4-W4),IF(ABS(N4-W4)<=ABS(O4-W4),"Offer 2","Offer 3"),IF(ABS(M4-W4)<=ABS(O4-W4),"Offer 1","Offer 3"))) -> Offer 1 | K4: 0.018 | L4: =IF(OR(I4="",K4=""),"",CEILING(I4*(1+K4),5)) -> 1975 | M4: =IF(I4="","",IF(X4="Under",CEILING(MAX(I4*1.02,MIN(V4,W4)*0.95),5),CEILING(MAX(I4*1.03,MIN(V4,W4)*0.97),5))) -> 2000 | N4: =IF(I4="","",IF(X4="Under",CEILING(MAX(I4*1.03,(V4+W4)/2*0.96),5),CEILING(MAX(I4*1.05,(V4+W4)/2*0.98),5))) -> 2035 | O4: =IF(I4="","",IF(X4="Under",CEILING(MAX(I4*1.05,MIN(V4,W4*1.01)),5),CEILING(MAX(I4*1.08,MIN(V4,W4*1.02)),5))) -> 2095 | P4: Investor Override | Q4: 46091 | T4: (904) 293-6422 | U4: 13 months / 2% increase / $250 concession | V4: =IF(C4="","",IFERROR(VLOOKUP(C4,SETUP!$A$9:$D$24,2,0),"⚠ Check SETUP")) -> 1969 | W4: =IF(C4="","",IFERROR(VLOOKUP(C4,SETUP!$A$9:$D$24,3,0),"⚠ Check SETUP")) -> 1617 | X4: =IF(C4="","",IFERROR(VLOOKUP(C4,SETUP!$A$9:$D$24,4,0),"⚠ Check SETUP")) -> Over | Y4: =IF(OR(I4="",M4=""),"",(M4-I4)/I4) -> 0.032524522 | Z4: =IF(OR(I4="",N4=""),"",(N4-I4)/I4) -> 0.050593702 | AA4: =IF(OR(I4="",O4=""),"",(O4-I4)/I4) -> 0.081569437 | AB4: =IF(OR(Q4="",S4<>"",P4="",I4=""),"",IF(P4="Investor Override",IF(L4="","",(L4-I4)/I4),IF(P4="Offer 1",IF(M4="","",(M4-I4)/I4),IF(P4="Offer 2",IF(N4="","",(N4-I4)/I4),IF(P4="Offer 3",IF(O4="","",(O4-I4)/I4),""))))) -> 0.019617966
A5: Tyson, Mikhal | B5: 1-1136 | C5: B1 | D5: 46146 | E5: =IF(D5="","",D5-90) -> 46056 | F5: =IF(D5="","",D5-60) -> 46086 | G5: =IF(D5="","",D5-30) -> 46116 | H5: 0 | I5: 2037 | J5: =IF(I5="","",IF(ABS(N5-W5)<=ABS(M5-W5),IF(ABS(N5-W5)<=ABS(O5-W5),"Offer 2","Offer 3"),IF(ABS(M5-W5)<=ABS(O5-W5),"Offer 1","Offer 3"))) -> Offer 1 | K5: 0 | L5: =IF(OR(I5="",K5=""),"",CEILING(I5*(1+K5),5)) -> 2040 | M5: =IF(I5="","",IF(X5="Under",CEILING(MAX(I5*1.02,MIN(V5,W5)*0.95),5),CEILING(MAX(I5*1.03,MIN(V5,W5)*0.97),5))) -> 2080 | N5: =IF(I5="","",IF(X5="Under",CEILING(MAX(I5*1.03,(V5+W5)/2*0.96),5),CEILING(MAX(I5*1.05,(V5+W5)/2*0.98),5))) -> 2100 | O5: =IF(I5="","",IF(X5="Under",CEILING(MAX(I5*1.05,MIN(V5,W5*1.01)),5),CEILING(MAX(I5*1.08,MIN(V5,W5*1.02)),5))) -> 2140 | P5: Investor Override | Q5: 46091 | T5: (904) 422-6933 | U5: 13 months / 0% increase / $500 concession | V5: =IF(C5="","",IFERROR(VLOOKUP(C5,SETUP!$A$9:$D$24,2,0),"⚠ Check SETUP")) -> 1809 | W5: =IF(C5="","",IFERROR(VLOOKUP(C5,SETUP!$A$9:$D$24,3,0),"⚠ Check SETUP")) -> 1764 | X5: =IF(C5="","",IFERROR(VLOOKUP(C5,SETUP!$A$9:$D$24,4,0),"⚠ Check SETUP")) -> Under | Y5: =IF(OR(I5="",M5=""),"",(M5-I5)/I5) -> 0.021109475 | Z5: =IF(OR(I5="",N5=""),"",(N5-I5)/I5) -> 0.030927835 | AA5: =IF(OR(I5="",O5=""),"",(O5-I5)/I5) -> 0.050564556 | AB5: =IF(OR(Q5="",S5<>"",P5="",I5=""),"",IF(P5="Investor Override",IF(L5="","",(L5-I5)/I5),IF(P5="Offer 1",IF(M5="","",(M5-I5)/I5),IF(P5="Offer 2",IF(N5="","",(N5-I5)/I5),IF(P5="Offer 3",IF(O5="","",(O5-I5)/I5),""))))) -> 0.0014727541
